Workbook

Sheet AYIRA MINI MART FINAL MENU - Pr
A1: Name | B1: Category | C1: Price | D1: Description | E1: Size | F1: Color | G1: Tag | H1: Brand | I1: Stock | J1: Availability | K1: Thumbnail | L1: Image1 | M1: Image2 | N1: Image2
A2: Mountain Dew 2.25L – ماونتن ديو 2.25 لتر | B2: Carbonated Soft Drinks – المشروبات الغازية | C2: 7.5 | D2: استمتع بـ ماونتن ديو، المشروب الغازي المنعش الذي يمنحك طاقة وحيوية في كل قطرة. يتميز بطعمه الرائع وتركيبته المميزة التي تجعله الخيار الأمثل لإرواء ظمأك في أي وقت. مثالي للحفلات والتجمعات العائلية والمناسبات المختلفة. يحتوي على نكهات متميزة تجعل كل رشفة تجربة لا تُنسى. احصل عليه الآن من أيرا ميني مارت بأفضل الأسعار وأعلى جودة. مشروبنا المميز يوفر لك الانتعاش الفوري ويلبي ذوقك الرفيع في كل لحظة تحتاج فيها إلى الترطيب. | J2: Show | K2: =IMAGE("https://cdn.store.link/products/ayiraminimart50505/qb3bg2-mountain%20dew%202.25%20l.png?versionId=_h55HFaLTDGEW0i5O0qGFO49KBQkdfzS")
A3: Pepsi 1.25L – بيبسي 1.25 لتر | B3: Carbonated Soft Drinks – المشروبات الغازية | C3: 4.5 | D3: استمتع بـ بيبسي، المشروب الغازي المنعش الذي يمنحك طاقة وحيوية في كل قطرة. يتميز بطعمه الرائع وتركيبته المميزة التي تجعله الخيار الأمثل لإرواء ظمأك في أي وقت. مثالي للحفلات والتجمعات العائلية والمناسبات المختلفة. يحتوي على نكهات متميزة تجعل كل رشفة تجربة لا تُنسى. احصل عليه الآن من أيرا ميني مارت بأفضل الأسعار وأعلى جودة. مشروبنا المميز يوفر لك الانتعاش الفوري ويلبي ذوقك الرفيع في كل لحظة تحتاج فيها إلى الترطيب. | J3: Show | K3: =IMAGE("https://cdn.store.link/products/ayiraminimart50505/ri64et-pepsi%201.25l.png?versionId=IwOw0VrxH9YWI05.XOKJTX_1pr40qp9A")
A4: Mountain Dew 1.25L – ماونتن ديو 1.25 لتر | B4: Carbonated Soft Drinks – المشروبات الغازية | C4: 4.5 | D4: استمتع بـ ماونتن ديو، المشروب الغازي المنعش الذي يمنحك طاقة وحيوية في كل قطرة. يتميز بطعمه الرائع وتركيبته المميزة التي تجعله الخيار الأمثل لإرواء ظمأك في أي وقت. مثالي للحفلات والتجمعات العائلية والمناسبات المختلفة. يحتوي على نكهات متميزة تجعل كل رشفة تجربة لا تُنسى. احصل عليه الآن من أيرا ميني مارت بأفضل الأسعار وأعلى جودة. مشروبنا المميز يوفر لك الانتعاش الفوري ويلبي ذوقك الرفيع في كل لحظة تحتاج فيها إلى الترطيب. | J4: Show | K4: =IMAGE("https://cdn.store.link/products/ayiraminimart50505/ywzsx7-mountain%20dew%201.25l.png?versionId=Bdv4AX2lHkgNWMqGNm0YVOnecfYpV1wq")
A5: Mountain Dew 330ml – ماونتن ديو 330 مل | B5: Carbonated Soft Drinks – المشروبات الغازية | C5: 2.5 | D5: استمتع بـ ماونتن ديو، المشروب الغازي المنعش الذي يمنحك طاقة وحيوية في كل قطرة. يتميز بطعمه الرائع وتركيبته المميزة التي تجعله الخيار الأمثل لإرواء ظمأك في أي وقت. مثالي للحفلات والتجمعات العائلية والمناسبات المختلفة. يحتوي على نكهات متميزة تجعل كل رشفة تجربة لا تُنسى. احصل عليه الآن من أيرا ميني مارت بأفضل الأسعار وأعلى جودة. مشروبنا المميز يوفر لك الانتعاش الفوري ويلبي ذوقك الرفيع في كل لحظة تحتاج فيها إلى الترطيب. | J5: Show | K5: =IMAGE("https://cdn.store.link/products/ayiraminimart50505/vk-4xp-mountain%20dew%20330%20ml.png?versionId=Nt5eIDm5bsvwUKxb81ZaEKTDV5HXVHxY")
A6: Shani Can 330ml – شاني – علبة 330 مل | B6: Carbonated Soft Drinks – المشروبات الغازية | C6: 2.5 | D6: استمتع بـ شاني، المشروب الغازي المنعش الذي يمنحك طاقة وحيوية في كل قطرة. يتميز بطعمه الرائع وتركيبته المميزة التي تجعله الخيار الأمثل لإرواء ظمأك في أي وقت. مثالي للحفلات والتجمعات العائلية والمناسبات المختلفة. يحتوي على نكهات متميزة تجعل كل رشفة تجربة لا تُنسى. احصل عليه الآن من أيرا ميني مارت بأفضل الأسعار وأعلى جودة. مشروبنا المميز يوفر لك الانتعاش الفوري ويلبي ذوقك الرفيع في كل لحظة تحتاج فيها إلى الترطيب. | J6: Show | K6: =IMAGE("https://cdn.store.link/products/ayiraminimart50505/qm36zv-shani%20fruit%20flavoured%20drink%20330%20ml.png?versionId=CNYiBdOUAINvEJ3IvXttsLNC39e9MwGw")
A7: 7Up 330ml – سفن أب 330 مل | B7: Carbonated Soft Drinks – المشروبات الغازية | C7: 2.5 | D7: استمتع بـ سفن أب، المشروب الغازي المنعش الذي يمنحك طاقة وحيوية في كل قطرة. يتميز بطعمه الرائع وتركيبته المميزة التي تجعله الخيار الأمثل لإرواء ظمأك في أي وقت. مثالي للحفلات والتجمعات العائلية والمناسبات المختلفة. يحتوي على نكهات متميزة تجعل كل رشفة تجربة لا تُنسى. احصل عليه الآن من أيرا ميني مارت بأفضل الأسعار وأعلى جودة. مشروبنا المميز يوفر لك الانتعاش الفوري ويلبي ذوقك الرفيع في كل لحظة تحتاج فيها إلى الترطيب. | J7: Show | K7: =IMAGE("https://cdn.store.link/products/ayiraminimart50505/rxr64e-refreshing%20lemon%20?versionId=vtzR9.iq85Qd_epQe4Hk2ExFcS0HkE7s")
A8: Mirinda Orange 1.25L – ميرندا برتقال 1.25 لتر | B8: Carbonated Soft Drinks – المشروبات الغازية | C8: 4.5 | D8: استمتع بـ ميرندا، المشروب الغازي المنعش الذي يمنحك طاقة وحيوية في كل قطرة. يتميز بطعمه الرائع وتركيبته المميزة التي تجعله الخيار الأمثل لإرواء ظمأك في أي وقت. مثالي للحفلات والتجمعات العائلية والمناسبات المختلفة. يحتوي على نكهات متميزة تجعل كل رشفة تجربة لا تُنسى. احصل عليه الآن من أيرا ميني مارت بأفضل الأسعار وأعلى جودة. مشروبنا المميز يوفر لك الانتعاش الفوري ويلبي ذوقك الرفيع في كل لحظة تحتاج فيها إلى الترطيب. | J8: Show | K8: =IMAGE("https://cdn.store.link/products/ayiraminimart50505/qxl8-5-mirinda%20orange%20bottle%201.25%20litres.png?versionId=IsndLwQrdZWw_0j9L32rEUStZzHgNcgy")
A9: Red Bull Sugar Free 250ml – ريد بول خالي من السكر 250 مل | B9: Energy & Sports Drinks – مشروبات الطاقة والرياضة | C9: 10 | D9: اشحن طاقتك مع ريد بول، مشروب الطاقة المفضل لدى الرياضيين والمحترفين. يمنحك التركيز والنشاط اللازمين لمواجهة تحديات اليوم بكفاءة عالية. بتركيبة فريدة من الكافيين والفيتامينات والأحماض الأمينية، يساعدك على الأداء بأقصى طاقتك. مثالي قبل التمرين الرياضي أو خلال ساعات العمل الطويلة. اكتشف الفرق مع كل رشفة وعش تجربة طاقة لا مثيل لها. متاح الآن في أيرا ميني مارت بسعر مناسب وجودة مضمونة. | J9: Show | K9: =IMAGE("https://cdn.store.link/products/ayiraminimart50505/jk50yg-red%20bull%20sugar%20free%20250ml.png?versionId=rO5I2j3ZWbAp2ajiWintHWyBg7Iv79jE")
A10: Red Bull Sea Blue Edition 250ml – ريد بُل سي بلو إديشن 250 مل | B10: Energy & Sports Drinks – مشروبات الطاقة والرياضة | C10: 10 | D10: اشحن طاقتك مع ريد بول، مشروب الطاقة المفضل لدى الرياضيين والمحترفين. يمنحك التركيز والنشاط اللازمين لمواجهة تحديات اليوم بكفاءة عالية. بتركيبة فريدة من الكافيين والفيتامينات والأحماض الأمينية، يساعدك على الأداء بأقصى طاقتك. مثالي قبل التمرين الرياضي أو خلال ساعات العمل الطويلة. اكتشف الفرق مع كل رشفة وعش تجربة طاقة لا مثيل لها. متاح الآن في أيرا ميني مارت بسعر مناسب وجودة مضمونة. | J10: Show | K10: =IMAGE("https://cdn.store.link/products/ayiraminimart50505/9r0v4c-red%20bull%20the%20sea%20blue%20edition%20%28cherry%20?versionId=sdDq3pJeZkcWXRjY6BGQhpxc2E1cTYDo")
A11: Red Bull White Edition Coconut Berry 250ml – ريد بُل وايت إديشن بنكهة جوز الهند والتوت 250 مل | B11: Energy & Sports Drinks – مشروبات الطاقة والرياضة | C11: 10 | D11: اشحن طاقتك مع ريد بول، مشروب الطاقة المفضل لدى الرياضيين والمحترفين. يمنحك التركيز والنشاط اللازمين لمواجهة تحديات اليوم بكفاءة عالية. بتركيبة فريدة من الكافيين والفيتامينات والأحماض الأمينية، يساعدك على الأداء بأقصى طاقتك. مثالي قبل التمرين الرياضي أو خلال ساعات العمل الطويلة. اكتشف الفرق مع كل رشفة وعش تجربة طاقة لا مثيل لها. متاح الآن في أيرا ميني مارت بسعر مناسب وجودة مضمونة. | J11: Show | K11: =IMAGE("https://cdn.store.link/products/ayiraminimart50505/b8x8pu-red%20bull%20the%20white%20edition%20%28coconut%20?versionId=vt6oRz6KnteH8MLOa8HCjcsP9awhQY8a")
A12: Red Bull Energy Drink 250ml – مشروب الطاقة ريد بُل 250 مل | B12: Energy & Sports Drinks – مشروبات الطاقة والرياضة | C12: 10 | D12: اشحن طاقتك مع ريد بول، مشروب الطاقة المفضل لدى الرياضيين والمحترفين. يمنحك التركيز والنشاط اللازمين لمواجهة تحديات اليوم بكفاءة عالية. بتركيبة فريدة من الكافيين والفيتامينات والأحماض الأمينية، يساعدك على الأداء بأقصى طاقتك. مثالي قبل التمرين الرياضي أو خلال ساعات العمل الطويلة. اكتشف الفرق مع كل رشفة وعش تجربة طاقة لا مثيل لها. متاح الآن في أيرا ميني مارت بسعر مناسب وجودة مضمونة. | J12: Show | K12: =IMAGE("https://cdn.store.link/products/ayiraminimart50505/c1tpch-red%20bull%20energy%20drink%20250%20ml.png?versionId=zjXM60JG3xmh0dZulGi1m5pjnnQ2SHok")
A13: Coca-Cola Sleek Can 330ml – كوكاكولا – علبة نحيفة 330 مل | B13: Carbonated Soft Drinks – المشروبات الغازية | C13: 2.5 | D13: استمتع بـ كوكاكولا، المشروب الغازي المنعش الذي يمنحك طاقة وحيوية في كل قطرة. يتميز بطعمه الرائع وتركيبته المميزة التي تجعله الخيار الأمثل لإرواء ظمأك في أي وقت. مثالي للحفلات والتجمعات العائلية والمناسبات المختلفة. يحتوي على نكهات متميزة تجعل كل رشفة تجربة لا تُنسى. احصل عليه الآن من أيرا ميني مارت بأفضل الأسعار وأعلى جودة. مشروبنا المميز يوفر لك الانتعاش الفوري ويلبي ذوقك الرفيع في كل لحظة تحتاج فيها إلى الترطيب. | J13: Show | K13: =IMAGE("https://cdn.store.link/products/ayiraminimart50505/iftisg-coca-cola%20sleek%20can%20330ml.png?versionId=tSPewvXz2qClB2r4WCg6gsrfe7A7zQ.E")
A14: 7Up 150ml – سفن أب 150 مل | B14: Carbonated Soft Drinks – المشروبات الغازية | C14: 2 | D14: استمتع بـ سفن أب، المشروب الغازي المنعش الذي يمنحك طاقة وحيوية في كل قطرة. يتميز بطعمه الرائع وتركيبته المميزة التي تجعله الخيار الأمثل لإرواء ظمأك في أي وقت. مثالي للحفلات والتجمعات العائلية والمناسبات المختلفة. يحتوي على نكهات متميزة تجعل كل رشفة تجربة لا تُنسى. احصل عليه الآن من أيرا ميني مارت بأفضل الأسعار وأعلى جودة. مشروبنا المميز يوفر لك الانتعاش الفوري ويلبي ذوقك الرفيع في كل لحظة تحتاج فيها إلى الترطيب. | J14: Show | K14: =IMAGE("https://cdn.store.link/products/ayiraminimart50505/p9o6hb-7up%20150ml.png?versionId=K32vu1YG3vHXk2ycHDw4ySVVX0HCXRMl")
A15: Mirinda Citrus 330ml – ميرندا الحمضيات 330 مل | B15: Carbonated Soft Drinks – المشروبات الغازية | C15: 2.5 | D15: استمتع بـ ميرندا، المشروب الغازي المنعش الذي يمنحك طاقة وحيوية في كل قطرة. يتميز بطعمه الرائع وتركيبته المميزة التي تجعله الخيار الأمثل لإرواء ظمأك في أي وقت. مثالي للحفلات والتجمعات العائلية والمناسبات المختلفة. يحتوي على نكهات متميزة تجعل كل رشفة تجربة لا تُنسى. احصل عليه الآن من أيرا ميني مارت بأفضل الأسعار وأعلى جودة. مشروبنا المميز يوفر لك الانتعاش الفوري ويلبي ذوقك الرفيع في كل لحظة تحتاج فيها إلى الترطيب. | J15: Show | K15: =IMAGE("https://cdn.store.link/products/ayiraminimart50505/eo98-i-mirinda%20citrus%20delicious%20?versionId=WxfWSpWiW4vkG7M.OfZzUbvNWCAaI0sb")
A16: Mirinda Apple 330ml – ميرندا تفاح 330 مل | B16: Carbonated Soft Drinks – المشروبات الغازية | C16: 2.5 | D16: استمتع بـ ميرندا، المشروب الغازي المنعش الذي يمنحك طاقة وحيوية في كل قطرة. يتميز بطعمه الرائع وتركيبته المميزة التي تجعله الخيار الأمثل لإرواء ظمأك في أي وقت. مثالي للحفلات والتجمعات العائلية والمناسبات المختلفة. يحتوي على نكهات متميزة تجعل كل رشفة تجربة لا تُنسى. احصل عليه الآن من أيرا ميني مارت بأفضل الأسعار وأعلى جودة. مشروبنا المميز يوفر لك الانتعاش الفوري ويلبي ذوقك الرفيع في كل لحظة تحتاج فيها إلى الترطيب. | J16: Show | K16: =IMAGE("https://cdn.store.link/products/ayiraminimart50505/knkvf7-mirinda%20green%20apple%20%E2%80%93%20delicious%20?versionId=WOKH4VzKx7gorw7Pd10DSDxZW_42hTmU")
A17: Double Up Fresh Breeze Mojito 350ml – موهيتو دبل أب نسيم منعش 350 مل | B17: Carbonated Soft Drinks – المشروبات الغازية | C17: 3.5 | D17: استمتع بـ دبل أب، المشروب الغازي المنعش الذي يمنحك طاقة وحيوية في كل قطرة. يتميز بطعمه الرائع وتركيبته المميزة التي تجعله الخيار الأمثل لإرواء ظمأك في أي وقت. مثالي للحفلات والتجمعات العائلية والمناسبات المختلفة. يحتوي على نكهات متميزة تجعل كل رشفة تجربة لا تُنسى. احصل عليه الآن من أيرا ميني مارت بأفضل الأسعار وأعلى جودة. مشروبنا المميز يوفر لك الانتعاش الفوري ويلبي ذوقك الرفيع في كل لحظة تحتاج فيها إلى الترطيب. | J17: Out of Stock | K17: =IMAGE("https://cdn.store.link/products/ayiraminimart50505/eg3h15-double%20up%20fresh%20breeze%20mojito%20350ml.png?versionId=t2KQp.FF_XlkBAAdWIGeJgGg9aegyoWU")
A18: Double Up Fresh Breeze Red Apple 350ml – دبل أب نسيم منعش بنكهة التفاح الأحمر 350 مل | B18: CARbonated Soft Drinks – المشروبات الغازية | C18: 3.5 | D18: استمتع بـ دبل أب، المشروب الغازي المنعش الذي يمنحك طاقة وحيوية في كل قطرة. يتميز بطعمه الرائع وتركيبته المميزة التي تجعله الخيار الأمثل لإرواء ظمأك في أي وقت. مثالي للحفلات والتجمعات العائلية والمناسبات المختلفة. يحتوي على نكهات متميزة تجعل كل رشفة تجربة لا تُنسى. احصل عليه الآن من أيرا ميني مارت بأفضل الأسعار وأعلى جودة. مشروبنا المميز يوفر لك الانتعاش الفوري ويلبي ذوقك الرفيع في كل لحظة تحتاج فيها إلى الترطيب. | J18: Out of Stock | K18: =IMAGE("https://cdn.store.link/products/ayiraminimart50505/zyt7ts-double%20up%20fresh%20breeze%20red%20apple%20350%20ml.png?versionId=fpHEijojcFQhvyo65gSzJj9Wibj4UvPh")
A19: RAYYAN Natural Water 330ml × 12 – مياه ريان طبيعية 330 مل × 12 | B19: Water – المياه | C19: 8 | D19: اشرب ريان، المياه النقية التي تعيد لجسمك توازنه الطبيعي. مستخرجة من أنقى المصادر الطبيعية ومعبأة بأعلى معايير الجودة والنظافة لضمان وصولها إليك بأفضل حالة. الترطيب الصحي أساس الحياة الجيدة، واختيارك لهذه المياه يعكس اهتمامك بصحتك. احرص على شرب كميات كافية يومياً للحفاظ على نشاطك وحيويتك. توفر لك أيرا ميني مارت هذه المياه الممتازة بأسعار تنافسية. | J19: Show | K19: =IMAGE("https://cdn.store.link/products/ayiraminimart50505/ln1vwn-rayyan%20natural%20water%20330ml%20%C3%97.png?versionId=b8X0bGBPFJKPKCfvzwwPcSgrlphEUJZw")
A20: Rayyan Natural Water 1.5L x 6 مياه ريان طبيعية 1.5 لتر × 6 | B20: Water – المياه | C20: 7 | D20: اشرب ريان، المياه النقية التي تعيد لجسمك توازنه الطبيعي. مستخرجة من أنقى المصادر الطبيعية ومعبأة بأعلى معايير الجودة والنظافة لضمان وصولها إليك بأفضل حالة. الترطيب الصحي أساس الحياة الجيدة، واختيارك لهذه المياه يعكس اهتمامك بصحتك. احرص على شرب كميات كافية يومياً للحفاظ على نشاطك وحيويتك. توفر لك أيرا ميني مارت هذه المياه الممتازة بأسعار تنافسية. | J20: Show | K20: =IMAGE("https://cdn.store.link/products/ayiraminimart50505/quwxhi-rayyan%20natural%20water%201.5l%20x%206.png?versionId=_zwzhTvzoK8RCWwXto3AV5BI9lJfRdwC")
A21: Qatar Oasis Natural Water 1.5L x 6 مياه قطر واحة الطبيعية – ١.٥ لتر × ٦ زجاجات | B21: Water – المياه | C21: 6 | D21: اشرب Qatar Oasis Natural Water 1.5L x 6 مياه قطر واحة الطبيعية – ١.٥ لتر × ٦ زجاجات، المياه النقية التي تعيد لجسمك توازنه الطبيعي. مستخرجة من أنقى المصادر الطبيعية ومعبأة بأعلى معايير الجودة والنظافة لضمان وصولها إليك بأفضل حالة. الترطيب الصحي أساس الحياة الجيدة، واختيارك لهذه المياه يعكس اهتمامك بصحتك. احرص على شرب كميات كافية يومياً للحفاظ على نشاطك وحيويتك. توفر لك أيرا ميني مارت هذه المياه الممتازة بأسعار تنافسية. | J21: Show | K21: =IMAGE("https://cdn.store.link/products/ayiraminimart50505/5zi9qe-qatar%20oasis%20natural%20water%201.5l%20x%206.png?versionId=OiM87o5wA.aLUizcFUKInz9gA_2TO6fR")
A22: Amwaj Mineral Water 1.5L x 6 مياه أمواج المعدنية 1.5 لتر × 6 | B22: Water – المياه | C22: 12 | D22: اشرب Amwaj Mineral Water 1.5L x 6 مياه أمواج المعدنية 1.5 لتر × 6، المياه النقية التي تعيد لجسمك توازنه الطبيعي. مستخرجة من أنقى المصادر الطبيعية ومعبأة بأعلى معايير الجودة والنظافة لضمان وصولها إليك بأفضل حالة. الترطيب الصحي أساس الحياة الجيدة، واختيارك لهذه المياه يعكس اهتمامك بصحتك. احرص على شرب كميات كافية يومياً للحفاظ على نشاطك وحيويتك. توفر لك أيرا ميني مارت هذه المياه الممتازة بأسعار تنافسية. | J22: Hide | K22: =IMAGE("https://cdn.store.link/products/ayiraminimart50505/d2y0fi-amwaj%20mineral%20water%20330ml%20x%20300.png?versionId=.uzgGg.LYAKPaUsf21m8xN565W_Rkk2M")
A23: Amwaj Mineral Water 330ml x 30 مياه أمواج المع30 مل × 30 | B23: Water – المياه | C23: 12 | D23: اشرب Amwaj Mineral Water 330ml x 300 مياه أمواج المعدنية 330 مل × 30، المياه النقية التي تعيد لجسمك توازنه الطبيعي. مستخرجة من أنقى المصادر الطبيعية ومعبأة بأعلى معايير الجودة والنظافة لضمان وصولها إليك بأفضل حالة. الترطيب الصحي أساس الحياة الجيدة، واختيارك لهذه المياه يعكس اهتمامك بصحتك. احرص على شرب كميات كافية يومياً للحفاظ على نشاطك وحيويتك. توفر لك أيرا ميني مارت هذه المياه الممتازة بأسعار تنافسية. | J23: Show | K23: =IMAGE("https://cdn.store.link/products/ayiraminimart50505/38l454-amajwaj.png?versionId=iQWNF9p8gKuJBXlJf2hcI_q4zHeUtv5E")
A24: Rayyan Mineral Water 330ml x 30 مياه ريان المعدنية 330 مل × 30 | B24: Water – المياه | C24: 15 | D24: اشرب ريان، المياه النقية التي تعيد لجسمك توازنه الطبيعي. مستخرجة من أنقى المصادر الطبيعية ومعبأة بأعلى معايير الجودة والنظافة لضمان وصولها إليك بأفضل حالة. الترطيب الصحي أساس الحياة الجيدة، واختيارك لهذه المياه يعكس اهتمامك بصحتك. احرص على شرب كميات كافية يومياً للحفاظ على نشاطك وحيويتك. توفر لك أيرا ميني مارت هذه المياه الممتازة بأسعار تنافسية. | J24: Show | K24: =IMAGE("https://cdn.store.link/products/ayiraminimart50505/70c2d6-rayyan%20mineral%20water%20330ml%20x%2030.png?versionId=kvZ2sXItQcz9sVcWjsOZsh4bJSucDbtZ")
A25: Rayyan Mineral Water 200ml x 30 مياه ريان المعدنية 200 مل × 30 | B25: Water – المياه | C25: 14 | D25: اشرب ريان، المياه النقية التي تعيد لجسمك توازنه الطبيعي. مستخرجة من أنقى المصادر الطبيعية ومعبأة بأعلى معايير الجودة والنظافة لضمان وصولها إليك بأفضل حالة. الترطيب الصحي أساس الحياة الجيدة، واختيارك لهذه المياه يعكس اهتمامك بصحتك. احرص على شرب كميات كافية يومياً للحفاظ على نشاطك وحيويتك. توفر لك أيرا ميني مارت هذه المياه الممتازة بأسعار تنافسية. | J25: Show | K25: =IMAGE("https://cdn.store.link/products/ayiraminimart50505/rven3m-rayyan%20mineral%20water%20200ml%20x%2030.png?versionId=pP_QgVTi1tpySwkJ9Sz5q0atEm6Q5_bp")
A26: Rayyan Natural Water 330ml x 12 مياه ريان طبيعية 330 مل × 12 | B26: Water – المياه | C26: 8 | D26: اشرب ريان، المياه النقية التي تعيد لجسمك توازنه الطبيعي. مستخرجة من أنقى المصادر الطبيعية ومعبأة بأعلى معايير الجودة والنظافة لضمان وصولها إليك بأفضل حالة. الترطيب الصحي أساس الحياة الجيدة، واختيارك لهذه المياه يعكس اهتمامك بصحتك. احرص على شرب كميات كافية يومياً للحفاظ على نشاطك وحيويتك. توفر لك أيرا ميني مارت هذه المياه الممتازة بأسعار تنافسية. | J26: Show | K26: =IMAGE("https://cdn.store.link/products/ayiraminimart50505/22hm6w-rayyan%20natural%20water%20330ml%20x%2012.png?versionId=7nJomvh4Gi4UP2aPfKQOwbqlROlD9y3J")
A27: Rayyan Alkaline Mineral Water 1.5L x 6 مياه ريان القلوية المعدنية 1.5 لتر × 6 | B27: Water – المياه | C27: 9 | D27: اشرب ريان، المياه النقية التي تعيد لجسمك توازنه الطبيعي. مستخرجة من أنقى المصادر الطبيعية ومعبأة بأعلى معايير الجودة والنظافة لضمان وصولها إليك بأفضل حالة. الترطيب الصحي أساس الحياة الجيدة، واختيارك لهذه المياه يعكس اهتمامك بصحتك. احرص على شرب كميات كافية يومياً للحفاظ على نشاطك وحيويتك. توفر لك أيرا ميني مارت هذه المياه الممتازة بأسعار تنافسية. | J27: Show | K27: =IMAGE("https://cdn.store.link/products/ayiraminimart50505/mrs9sz-rayyan%20alkaline%20mineral%20water%201.5l%20x%206.png?versionId=vXqueSmDcIkOC4aDly2g1tBReH4lkwwZ")
A28: Arwa Water 12pcs | B28: Water – المياه | C28: 9 | J28: Show | K28: =IMAGE("https://cdn.store.link/products/ayiraminimart50505/5fltvp-arwa%20water.png?versionId=mytNle2wMMYsXMYxlMzly7FWNxAZ9ADn")
A29: Pran Basil Seed Lychee 250 ml بران بذور الريحان بنكهة الليتشي بحجم 250 مل | B29: Juices & Fruit Drinks – العصائر ومشروبات الفاكهة | C29: 2 | D29: اكتشف Pran Basil Seed Lychee 250 ml بران بذور الريحان بنكهة الليتشي بحجم 250 مل، المنتج المميز الذي يجمع بين الجودة العالية والقيمة الرائعة. مصنوع وفق أعلى معايير الجودة والسلامة لضمان رضاك التام في كل مرة. يتميز بمواصفاته الممتازة التي تجعله الخيار الأفضل لك ولعائلتك. سواء للاستخدام اليومي أو للمناسبات الخاصة، فهو يلبي توقعاتك ويتجاوزها. احصل عليه الآن من أيرا ميني مارت واستمتع بتجربة شراء ممتعة وموثوقة. | J29: Show | K29: =IMAGE("https://cdn.store.link/products/ayiraminimart50505/dkyvk5-pran%20basil%20seed%20lychee%20250%20ml.png?versionId=v0ofL6YjCnmyaqsiz7BxtUP_txXEv404")
A30: KDD Cocktail Fruit Drink 250ml – مشروب كوكتيل فواكه كي دي دي 250 مل | B30: Juices & Fruit Drinks – العصائر ومشروبات الفاكهة | C30: 2 | D30: استمتع بـ كي دي دي، المشروب الغازي المنعش الذي يمنحك طاقة وحيوية في كل قطرة. يتميز بطعمه الرائع وتركيبته المميزة التي تجعله الخيار الأمثل لإرواء ظمأك في أي وقت. مثالي للحفلات والتجمعات العائلية والمناسبات المختلفة. يحتوي على نكهات متميزة تجعل كل رشفة تجربة لا تُنسى. احصل عليه الآن من أيرا ميني مارت بأفضل الأسعار وأعلى جودة. مشروبنا المميز يوفر لك الانتعاش الفوري ويلبي ذوقك الرفيع في كل لحظة تحتاج فيها إلى الترطيب. | J30: Show | K30: =IMAGE("https://cdn.store.link/products/ayiraminimart50505/qy5utg-kdd%20cocktail%20fruit%20drink%20180%20ml.png?versionId=8d_GsxfztSS2pDGO.s2_dL938YDVRFzI")
A31: KDD Cherry Drink 250 ml – كي دي دي كرز مشروب 250 مل | B31: Juices & Fruit Drinks – العصائر ومشروبات الفاكهة | C31: 2.5 | D31: استمتع بـ كي دي دي، المشروب الغازي المنعش الذي يمنحك طاقة وحيوية في كل قطرة. يتميز بطعمه الرائع وتركيبته المميزة التي تجعله الخيار الأمثل لإرواء ظمأك في أي وقت. مثالي للحفلات والتجمعات العائلية والمناسبات المختلفة. يحتوي على نكهات متميزة تجعل كل رشفة تجربة لا تُنسى. احصل عليه الآن من أيرا ميني مارت بأفضل الأسعار وأعلى جودة. مشروبنا المميز يوفر لك الانتعاش الفوري ويلبي ذوقك الرفيع في كل لحظة تحتاج فيها إلى الترطيب. | J31: Show | K31: =IMAGE("https://cdn.store.link/products/ayiraminimart50505/mc010h-kdd%20cherry%20drink%20250%20ml.png?versionId=vE.YCuKGdBhfkrJHSuLqYZNwMDp8W8rz")
A32: KDD Guava Nectar 250 ml – كي دي دي جوافة نكتار 250 مل | B32: Juices & Fruit Drinks – العصائر ومشروبات الفاكهة | C32: 2.5 | D32: احرص على صحتك مع كي دي دي، العصير الطازج الغني بالفيتامينات والمعادن الضرورية لصحة جسمك. مصنوع من أجود الفواكه المختارة بعناية لتمنحك طعماً رائعاً وفائدة غذائية عالية. يمنحك الطاقة الطبيعية ويعزز جهازك المناعي بفضل محتواه الغني. مثالي للإفطار اليومي أو كمشروب صحي في أي وقت. اطلبه الآن من أيرا ميني مارت واستمتع بكل قطرة من هذا العصير اللذيذ والمفيد. | J32: Show | K32: =IMAGE("https://cdn.store.link/products/ayiraminimart50505/ulwg6b-kdd%20guava%20nectar%20250%20ml.png?versionId=S77h7Y91F8nclznUQwE.p9ZoXCGmuDmF")
A33: KDD Mango Nectar 250 ml – كي دي دي مانجو نكتار 250 مل | B33: Juices & Fruit Drinks – العصائر ومشروبات الفاكهة | C33: 2.5 | D33: احرص على صحتك مع كي دي دي، العصير الطازج الغني بالفيتامينات والمعادن الضرورية لصحة جسمك. مصنوع من أجود الفواكه المختارة بعناية لتمنحك طعماً رائعاً وفائدة غذائية عالية. يمنحك الطاقة الطبيعية ويعزز جهازك المناعي بفضل محتواه الغني. مثالي للإفطار اليومي أو كمشروب صحي في أي وقت. اطلبه الآن من أيرا ميني مارت واستمتع بكل قطرة من هذا العصير اللذيذ والمفيد. | J33: Show | K33: =IMAGE("https://cdn.store.link/products/ayiraminimart50505/s96wfq-kdd%20mango%20nectar%20250%20ml.png?versionId=0w.PKY58A11MAJci1pF6fX._DEBbbHUb")
A34: KDD 100% Pineapple Juice 250 ml – كي دي دي 100% أناناس عصير 250 مل | B34: Juices & Fruit Drinks – العصائر ومشروبات الفاكهة | C34: 2.5 | D34: احرص على صحتك مع كي دي دي، العصير الطازج الغني بالفيتامينات والمعادن الضرورية لصحة جسمك. مصنوع من أجود الفواكه المختارة بعناية لتمنحك طعماً رائعاً وفائدة غذائية عالية. يمنحك الطاقة الطبيعية ويعزز جهازك المناعي بفضل محتواه الغني. مثالي للإفطار اليومي أو كمشروب صحي في أي وقت. اطلبه الآن من أيرا ميني مارت واستمتع بكل قطرة من هذا العصير اللذيذ والمفيد. | J34: Show | K34: =IMAGE("https://cdn.store.link/products/ayiraminimart50505/gapcdl-kdd%2520100%25%2520pineapple%2520juice%2520250%2520ml.png?versionId=To8kDi8TYbikYEOd9FkrNzPaLXlLneI9")
A35: KDD 100% Apple Juice 250 ml – كي دي دي 100% تفاح عصير 250 مل | B35: Juices & Fruit Drinks – العصائر ومشروبات الفاكهة | C35: 2.5 | D35: احرص على صحتك مع كي دي دي، العصير الطازج الغني بالفيتامينات والمعادن الضرورية لصحة جسمك. مصنوع من أجود الفواكه المختارة بعناية لتمنحك طعماً رائعاً وفائدة غذائية عالية. يمنحك الطاقة الطبيعية ويعزز جهازك المناعي بفضل محتواه الغني. مثالي للإفطار اليومي أو كمشروب صحي في أي وقت. اطلبه الآن من أيرا ميني مارت واستمتع بكل قطرة من هذا العصير اللذيذ والمفيد. | J35: Show | K35: =IMAGE("https://cdn.store.link/products/ayiraminimart50505/loocib-kdd%2520100%25%2520apple%2520juice%2520250%2520ml.png?versionId=Wum2AQQKg4PWeN.J_ZpBxdX7BdPcEKsi")
A36: KDD 100% Orange Juice 250 ml – كي دي دي 100% برتقال عصير 250 مل | B36: Juices & Fruit Drinks – العصائر ومشروبات الفاكهة | C36: 2.5 | D36: احرص على صحتك مع كي دي دي، العصير الطازج الغني بالفيتامينات والمعادن الضرورية لصحة جسمك. مصنوع من أجود الفواكه المختارة بعناية لتمنحك طعماً رائعاً وفائدة غذائية عالية. يمنحك الطاقة الطبيعية ويعزز جهازك المناعي بفضل محتواه الغني. مثالي للإفطار اليومي أو كمشروب صحي في أي وقت. اطلبه الآن من أيرا ميني مارت واستمتع بكل قطرة من هذا العصير اللذيذ والمفيد. | J36: Show | K36: =IMAGE("https://cdn.store.link/products/ayiraminimart50505/loocib-kdd%2520100%25%2520apple%2520juice%2520250%2520ml.png?versionId=Wum2AQQKg4PWeN.J_ZpBxdX7BdPcEKsi")
A37: KDD Peach Nectar 250 ml – كي دي دي خوخ نكتار 250 مل | B37: Juices & Fruit Drinks – العصائر ومشروبات الفاكهة | C37: 2.5 | D37: احرص على صحتك مع كي دي دي، العصير الطازج الغني بالفيتامينات والمعادن الضرورية لصحة جسمك. مصنوع من أجود الفواكه المختارة بعناية لتمنحك طعماً رائعاً وفائدة غذائية عالية. يمنحك الطاقة الطبيعية ويعزز جهازك المناعي بفضل محتواه الغني. مثالي للإفطار اليومي أو كمشروب صحي في أي وقت. اطلبه الآن من أيرا ميني مارت واستمتع بكل قطرة من هذا العصير اللذيذ والمفيد. | J37: Show | K37: =IMAGE("https://cdn.store.link/products/ayiraminimart50505/thds7c-kdd%2520100%25%2520orange%2520juice%2520250%2520ml.png?versionId=.SvI0ueWIvsEq6ygSLoC1iOsH3kPSqcd")
A38: KDD Cocktail Fruit Drink 180 ml – كي دي دي Cocktail Fruit مشروب 180 مل | B38: Juices & Fruit Drinks – العصائر ومشروبات الفاكهة | C38: 2 | D38: استمتع بـ كي دي دي، المشروب الغازي المنعش الذي يمنحك طاقة وحيوية في كل قطرة. يتميز بطعمه الرائع وتركيبته المميزة التي تجعله الخيار الأمثل لإرواء ظمأك في أي وقت. مثالي للحفلات والتجمعات العائلية والمناسبات المختلفة. يحتوي على نكهات متميزة تجعل كل رشفة تجربة لا تُنسى. احصل عليه الآن من أيرا ميني مارت بأفضل الأسعار وأعلى جودة. مشروبنا المميز يوفر لك الانتعاش الفوري ويلبي ذوقك الرفيع في كل لحظة تحتاج فيها إلى الترطيب. | J38: Show | K38: =IMAGE("https://cdn.store.link/products/ayiraminimart50505/2qcepq-kdd%20peach%20nectar%20250%20ml.png?versionId=_hxsR.rSrdBi4VVXkrM3FxG9X9ceC60h")
A39: KDD 100% Orange Juice 180 ml – كي دي دي 100% برتقال عصير 180 مل | B39: Juices & Fruit Drinks – العصائر ومشروبات الفاكهة | C39: 2 | D39: احرص على صحتك مع كي دي دي، العصير الطازج الغني بالفيتامينات والمعادن الضرورية لصحة جسمك. مصنوع من أجود الفواكه المختارة بعناية لتمنحك طعماً رائعاً وفائدة غذائية عالية. يمنحك الطاقة الطبيعية ويعزز جهازك المناعي بفضل محتواه الغني. مثالي للإفطار اليومي أو كمشروب صحي في أي وقت. اطلبه الآن من أيرا ميني مارت واستمتع بكل قطرة من هذا العصير اللذيذ والمفيد. | J39: Show | K39: =IMAGE("https://cdn.store.link/products/ayiraminimart50505/qy5utg-kdd%20cocktail%20fruit%20drink%20180%20ml.png?versionId=8d_GsxfztSS2pDGO.s2_dL938YDVRFzI")
A40: KDD Guava Nectar 180 ml – كي دي دي جوافة نكتار 180 مل | B40: Juices & Fruit Drinks – العصائر ومشروبات الفاكهة | C40: 2 | D40: احرص على صحتك مع كي دي دي، العصير الطازج الغني بالفيتامينات والمعادن الضرورية لصحة جسمك. مصنوع من أجود الفواكه المختارة بعناية لتمنحك طعماً رائعاً وفائدة غذائية عالية. يمنحك الطاقة الطبيعية ويعزز جهازك المناعي بفضل محتواه الغني. مثالي للإفطار اليومي أو كمشروب صحي في أي وقت. اطلبه الآن من أيرا ميني مارت واستمتع بكل قطرة من هذا العصير اللذيذ والمفيد. | J40: Show | K40: =IMAGE("https://cdn.store.link/products/ayiraminimart50505/e1gce8-kdd%20guava%20nectar%20180%20ml.png?versionId=RAVFQKHBrUfRsM8E0SJvM0ckFUhTp.wO")
...

Sheet English Products
A1: Name | B1: Category | C1: Price | D1: Description | E1: Thumbnail | L1: Image1 | M1: Image2 | N1: Image2
A2: =IFERROR(__xludf.DUMMYFUNCTION("IF('AYIRA MINI MART FINAL MENU - Pr'!A2="""", """", IF(LEN(IFERROR(TRIM(REGEXREPLACE(TRIM(REGEXEXTRACT('AYIRA MINI MART FINAL MENU - Pr'!A2, ""^[^\x{0600}-\x{06FF}]+"")), ""[-–]+$"", """")), """"))>0, IFERROR(TRIM(REGEXREPLACE(TRIM(REGEXEXTRACT('AYIRA MIN"&"I MART FINAL MENU - Pr'!A2, ""^[^\x{0600}-\x{06FF}]+"")), ""[-–]+$"", """")), """"), GOOGLETRANSLATE('AYIRA MINI MART FINAL MENU - Pr'!A2, ""ar"", ""en"")))"),"Mountain Dew 2.25L") -> Mountain Dew 2.25L | B2: =IFERROR(__xludf.DUMMYFUNCTION("IF('AYIRA MINI MART FINAL MENU - Pr'!B2="""", """", IF(LEN(IFERROR(TRIM(REGEXREPLACE(TRIM(REGEXEXTRACT('AYIRA MINI MART FINAL MENU - Pr'!B2, ""^[^\x{0600}-\x{06FF}]+"")), ""[-–]+$"", """")), """"))>0, IFERROR(TRIM(REGEXREPLACE(TRIM(REGEXEXTRACT('AYIRA MIN"&"I MART FINAL MENU - Pr'!B2, ""^[^\x{0600}-\x{06FF}]+"")), ""[-–]+$"", """")), """"), GOOGLETRANSLATE('AYIRA MINI MART FINAL MENU - Pr'!B2, ""ar"", ""en"")))"),"Carbonated Soft Drinks") -> Carbonated Soft Drinks | C2: =IF('AYIRA MINI MART FINAL MENU - Pr'!C2="", "", 'AYIRA MINI MART FINAL MENU - Pr'!C2) -> 7.5 | D2: =IFERROR(__xludf.DUMMYFUNCTION("IF('AYIRA MINI MART FINAL MENU - Pr'!D2="""", """", GOOGLETRANSLATE('AYIRA MINI MART FINAL MENU - Pr'!D2, ""ar"", ""en""))"),"Enjoy Mountain Dew, the refreshing soft drink that gives you energy and vitality with every sip. Its great taste and unique formula make it the perfect choice to quench your thirst anytime. Ideal for parties, family gatherings, and various occasions. It b"&"oasts distinctive flavors that make every sip an unforgettable experience. Get it now from Aira Mini Mart at the best prices and highest quality. Our premium drink provides instant refreshment and satisfies your discerning palate whenever you need hydrati"&"on.") -> Enjoy Mountain Dew, the refreshing soft drink that gives you energy and vitality with every sip. Its great taste and unique formula make it the perfect choice to quench your thirst anytime. Ideal for parties, family gatherings, and various occasions. It boasts distinctive flavors that make every sip an unforgettable experience. Get it now from Aira Mini Mart at the best prices and highest quality. Our premium drink provides instant refreshment and satisfies your discerning palate whenever you need hydration. | E2: =IF('AYIRA MINI MART FINAL MENU - Pr'!K2="", "", 'AYIRA MINI MART FINAL MENU - Pr'!K2) | L2: =IF('AYIRA MINI MART FINAL MENU - Pr'!L2="", "", 'AYIRA MINI MART FINAL MENU - Pr'!L2) | M2: =IF('AYIRA MINI MART FINAL MENU - Pr'!M2="", "", 'AYIRA MINI MART FINAL MENU - Pr'!M2) | N2: =IF('AYIRA MINI MART FINAL MENU - Pr'!N2="", "", 'AYIRA MINI MART FINAL MENU - Pr'!N2)
A3: =IFERROR(__xludf.DUMMYFUNCTION("IF('AYIRA MINI MART FINAL MENU - Pr'!A3="""", """", IF(LEN(IFERROR(TRIM(REGEXREPLACE(TRIM(REGEXEXTRACT('AYIRA MINI MART FINAL MENU - Pr'!A3, ""^[^\x{0600}-\x{06FF}]+"")), ""[-–]+$"", """")), """"))>0, IFERROR(TRIM(REGEXREPLACE(TRIM(REGEXEXTRACT('AYIRA MIN"&"I MART FINAL MENU - Pr'!A3, ""^[^\x{0600}-\x{06FF}]+"")), ""[-–]+$"", """")), """"), GOOGLETRANSLATE('AYIRA MINI MART FINAL MENU - Pr'!A3, ""ar"", ""en"")))"),"Pepsi 1.25L") -> Pepsi 1.25L | B3: =IFERROR(__xludf.DUMMYFUNCTION("IF('AYIRA MINI MART FINAL MENU - Pr'!B3="""", """", IF(LEN(IFERROR(TRIM(REGEXREPLACE(TRIM(REGEXEXTRACT('AYIRA MINI MART FINAL MENU - Pr'!B3, ""^[^\x{0600}-\x{06FF}]+"")), ""[-–]+$"", """")), """"))>0, IFERROR(TRIM(REGEXREPLACE(TRIM(REGEXEXTRACT('AYIRA MIN"&"I MART FINAL MENU - Pr'!B3, ""^[^\x{0600}-\x{06FF}]+"")), ""[-–]+$"", """")), """"), GOOGLETRANSLATE('AYIRA MINI MART FINAL MENU - Pr'!B3, ""ar"", ""en"")))"),"Carbonated Soft Drinks") -> Carbonated Soft Drinks | C3: =IF('AYIRA MINI MART FINAL MENU - Pr'!C3="", "", 'AYIRA MINI MART FINAL MENU - Pr'!C3) -> 4.5 | D3: =IFERROR(__xludf.DUMMYFUNCTION("IF('AYIRA MINI MART FINAL MENU - Pr'!D3="""", """", GOOGLETRANSLATE('AYIRA MINI MART FINAL MENU - Pr'!D3, ""ar"", ""en""))"),"Enjoy Pepsi, the refreshing soft drink that gives you energy and vitality with every drop. Its great taste and unique formula make it the perfect choice to quench your thirst anytime. Ideal for parties, family gatherings, and various occasions. It contain"&"s distinctive flavors that make every sip an unforgettable experience. Get it now from Aira Mini Mart at the best prices and highest quality. Our premium drink provides you with instant refreshment and satisfies your discerning taste whenever you need hyd"&"ration.") -> Enjoy Pepsi, the refreshing soft drink that gives you energy and vitality with every drop. Its great taste and unique formula make it the perfect choice to quench your thirst anytime. Ideal for parties, family gatherings, and various occasions. It contains distinctive flavors that make every sip an unforgettable experience. Get it now from Aira Mini Mart at the best prices and highest quality. Our premium drink provides you with instant refreshment and satisfies your discerning taste whenever you need hydration. | E3: =IF('AYIRA MINI MART FINAL MENU - Pr'!K3="", "", 'AYIRA MINI MART FINAL MENU - Pr'!K3) | L3: =IF('AYIRA MINI MART FINAL MENU - Pr'!L3="", "", 'AYIRA MINI MART FINAL MENU - Pr'!L3) | M3: =IF('AYIRA MINI MART FINAL MENU - Pr'!M3="", "", 'AYIRA MINI MART FINAL MENU - Pr'!M3) | N3: =IF('AYIRA MINI MART FINAL MENU - Pr'!N3="", "", 'AYIRA MINI MART FINAL MENU - Pr'!N3)
A4: =IFERROR(__xludf.DUMMYFUNCTION("IF('AYIRA MINI MART FINAL MENU - Pr'!A4="""", """", IF(LEN(IFERROR(TRIM(REGEXREPLACE(TRIM(REGEXEXTRACT('AYIRA MINI MART FINAL MENU - Pr'!A4, ""^[^\x{0600}-\x{06FF}]+"")), ""[-–]+$"", """")), """"))>0, IFERROR(TRIM(REGEXREPLACE(TRIM(REGEXEXTRACT('AYIRA MIN"&"I MART FINAL MENU - Pr'!A4, ""^[^\x{0600}-\x{06FF}]+"")), ""[-–]+$"", """")), """"), GOOGLETRANSLATE('AYIRA MINI MART FINAL MENU - Pr'!A4, ""ar"", ""en"")))"),"Mountain Dew 1.25L") -> Mountain Dew 1.25L | B4: =IFERROR(__xludf.DUMMYFUNCTION("IF('AYIRA MINI MART FINAL MENU - Pr'!B4="""", """", IF(LEN(IFERROR(TRIM(REGEXREPLACE(TRIM(REGEXEXTRACT('AYIRA MINI MART FINAL MENU - Pr'!B4, ""^[^\x{0600}-\x{06FF}]+"")), ""[-–]+$"", """")), """"))>0, IFERROR(TRIM(REGEXREPLACE(TRIM(REGEXEXTRACT('AYIRA MIN"&"I MART FINAL MENU - Pr'!B4, ""^[^\x{0600}-\x{06FF}]+"")), ""[-–]+$"", """")), """"), GOOGLETRANSLATE('AYIRA MINI MART FINAL MENU - Pr'!B4, ""ar"", ""en"")))"),"Carbonated Soft Drinks") -> Carbonated Soft Drinks | C4: =IF('AYIRA MINI MART FINAL MENU - Pr'!C4="", "", 'AYIRA MINI MART FINAL MENU - Pr'!C4) -> 4.5 | D4: =IFERROR(__xludf.DUMMYFUNCTION("IF('AYIRA MINI MART FINAL MENU - Pr'!D4="""", """", GOOGLETRANSLATE('AYIRA MINI MART FINAL MENU - Pr'!D4, ""ar"", ""en""))"),"Enjoy Mountain Dew, the refreshing soft drink that gives you energy and vitality with every sip. Its great taste and unique formula make it the perfect choice to quench your thirst anytime. Ideal for parties, family gatherings, and various occasions. It b"&"oasts distinctive flavors that make every sip an unforgettable experience. Get it now from Aira Mini Mart at the best prices and highest quality. Our premium drink provides instant refreshment and satisfies your discerning palate whenever you need hydrati"&"on.") -> Enjoy Mountain Dew, the refreshing soft drink that gives you energy and vitality with every sip. Its great taste and unique formula make it the perfect choice to quench your thirst anytime. Ideal for parties, family gatherings, and various occasions. It boasts distinctive flavors that make every sip an unforgettable experience. Get it now from Aira Mini Mart at the best prices and highest quality. Our premium drink provides instant refreshment and satisfies your discerning palate whenever you need hydration. | E4: =IF('AYIRA MINI MART FINAL MENU - Pr'!K4="", "", 'AYIRA MINI MART FINAL MENU - Pr'!K4) | L4: =IF('AYIRA MINI MART FINAL MENU - Pr'!L4="", "", 'AYIRA MINI MART FINAL MENU - Pr'!L4) | M4: =IF('AYIRA MINI MART FINAL MENU - Pr'!M4="", "", 'AYIRA MINI MART FINAL MENU - Pr'!M4) | N4: =IF('AYIRA MINI MART FINAL MENU - Pr'!N4="", "", 'AYIRA MINI MART FINAL MENU - Pr'!N4)
A5: =IFERROR(__xludf.DUMMYFUNCTION("IF('AYIRA MINI MART FINAL MENU - Pr'!A5="""", """", IF(LEN(IFERROR(TRIM(REGEXREPLACE(TRIM(REGEXEXTRACT('AYIRA MINI MART FINAL MENU - Pr'!A5, ""^[^\x{0600}-\x{06FF}]+"")), ""[-–]+$"", """")), """"))>0, IFERROR(TRIM(REGEXREPLACE(TRIM(REGEXEXTRACT('AYIRA MIN"&"I MART FINAL MENU - Pr'!A5, ""^[^\x{0600}-\x{06FF}]+"")), ""[-–]+$"", """")), """"), GOOGLETRANSLATE('AYIRA MINI MART FINAL MENU - Pr'!A5, ""ar"", ""en"")))"),"Mountain Dew 330ml") -> Mountain Dew 330ml | B5: =IFERROR(__xludf.DUMMYFUNCTION("IF('AYIRA MINI MART FINAL MENU - Pr'!B5="""", """", IF(LEN(IFERROR(TRIM(REGEXREPLACE(TRIM(REGEXEXTRACT('AYIRA MINI MART FINAL MENU - Pr'!B5, ""^[^\x{0600}-\x{06FF}]+"")), ""[-–]+$"", """")), """"))>0, IFERROR(TRIM(REGEXREPLACE(TRIM(REGEXEXTRACT('AYIRA MIN"&"I MART FINAL MENU - Pr'!B5, ""^[^\x{0600}-\x{06FF}]+"")), ""[-–]+$"", """")), """"), GOOGLETRANSLATE('AYIRA MINI MART FINAL MENU - Pr'!B5, ""ar"", ""en"")))"),"Carbonated Soft Drinks") -> Carbonated Soft Drinks | C5: =IF('AYIRA MINI MART FINAL MENU - Pr'!C5="", "", 'AYIRA MINI MART FINAL MENU - Pr'!C5) -> 2.5 | D5: =IFERROR(__xludf.DUMMYFUNCTION("IF('AYIRA MINI MART FINAL MENU - Pr'!D5="""", """", GOOGLETRANSLATE('AYIRA MINI MART FINAL MENU - Pr'!D5, ""ar"", ""en""))"),"Enjoy Mountain Dew, the refreshing soft drink that gives you energy and vitality with every sip. Its great taste and unique formula make it the perfect choice to quench your thirst anytime. Ideal for parties, family gatherings, and various occasions. It b"&"oasts distinctive flavors that make every sip an unforgettable experience. Get it now from Aira Mini Mart at the best prices and highest quality. Our premium drink provides instant refreshment and satisfies your discerning palate whenever you need hydrati"&"on.") -> Enjoy Mountain Dew, the refreshing soft drink that gives you energy and vitality with every sip. Its great taste and unique formula make it the perfect choice to quench your thirst anytime. Ideal for parties, family gatherings, and various occasions. It boasts distinctive flavors that make every sip an unforgettable experience. Get it now from Aira Mini Mart at the best prices and highest quality. Our premium drink provides instant refreshment and satisfies your discerning palate whenever you need hydration. | E5: =IF('AYIRA MINI MART FINAL MENU - Pr'!K5="", "", 'AYIRA MINI MART FINAL MENU - Pr'!K5) | L5: =IF('AYIRA MINI MART FINAL MENU - Pr'!L5="", "", 'AYIRA MINI MART FINAL MENU - Pr'!L5) | M5: =IF('AYIRA MINI MART FINAL MENU - Pr'!M5="", "", 'AYIRA MINI MART FINAL MENU - Pr'!M5) | N5: =IF('AYIRA MINI MART FINAL MENU - Pr'!N5="", "", 'AYIRA MINI MART FINAL MENU - Pr'!N5)
A6: =IFERROR(__xludf.DUMMYFUNCTION("IF('AYIRA MINI MART FINAL MENU - Pr'!A6="""", """", IF(LEN(IFERROR(TRIM(REGEXREPLACE(TRIM(REGEXEXTRACT('AYIRA MINI MART FINAL MENU - Pr'!A6, ""^[^\x{0600}-\x{06FF}]+"")), ""[-–]+$"", """")), """"))>0, IFERROR(TRIM(REGEXREPLACE(TRIM(REGEXEXTRACT('AYIRA MIN"&"I MART FINAL MENU - Pr'!A6, ""^[^\x{0600}-\x{06FF}]+"")), ""[-–]+$"", """")), """"), GOOGLETRANSLATE('AYIRA MINI MART FINAL MENU - Pr'!A6, ""ar"", ""en"")))"),"Shani Can 330ml") -> Shani Can 330ml | B6: =IFERROR(__xludf.DUMMYFUNCTION("IF('AYIRA MINI MART FINAL MENU - Pr'!B6="""", """", IF(LEN(IFERROR(TRIM(REGEXREPLACE(TRIM(REGEXEXTRACT('AYIRA MINI MART FINAL MENU - Pr'!B6, ""^[^\x{0600}-\x{06FF}]+"")), ""[-–]+$"", """")), """"))>0, IFERROR(TRIM(REGEXREPLACE(TRIM(REGEXEXTRACT('AYIRA MIN"&"I MART FINAL MENU - Pr'!B6, ""^[^\x{0600}-\x{06FF}]+"")), ""[-–]+$"", """")), """"), GOOGLETRANSLATE('AYIRA MINI MART FINAL MENU - Pr'!B6, ""ar"", ""en"")))"),"Carbonated Soft Drinks") -> Carbonated Soft Drinks | C6: =IF('AYIRA MINI MART FINAL MENU - Pr'!C6="", "", 'AYIRA MINI MART FINAL MENU - Pr'!C6) -> 2.5 | D6: =IFERROR(__xludf.DUMMYFUNCTION("IF('AYIRA MINI MART FINAL MENU - Pr'!D6="""", """", GOOGLETRANSLATE('AYIRA MINI MART FINAL MENU - Pr'!D6, ""ar"", ""en""))"),"Enjoy Shani, the refreshing soft drink that gives you energy and vitality with every drop. Its delicious taste and unique formula make it the perfect choice to quench your thirst anytime. Ideal for parties, family gatherings, and various occasions. It boa"&"sts distinctive flavors that make every sip an unforgettable experience. Get it now from Aira Mini Mart at the best prices and highest quality. Our premium drink provides instant refreshment and satisfies your discerning palate whenever you need hydration"&".") -> Enjoy Shani, the refreshing soft drink that gives you energy and vitality with every drop. Its delicious taste and unique formula make it the perfect choice to quench your thirst anytime. Ideal for parties, family gatherings, and various occasions. It boasts distinctive flavors that make every sip an unforgettable experience. Get it now from Aira Mini Mart at the best prices and highest quality. Our premium drink provides instant refreshment and satisfies your discerning palate whenever you need hydration. | E6: =IF('AYIRA MINI MART FINAL MENU - Pr'!K6="", "", 'AYIRA MINI MART FINAL MENU - Pr'!K6) | L6: =IF('AYIRA MINI MART FINAL MENU - Pr'!L6="", "", 'AYIRA MINI MART FINAL MENU - Pr'!L6) | M6: =IF('AYIRA MINI MART FINAL MENU - Pr'!M6="", "", 'AYIRA MINI MART FINAL MENU - Pr'!M6) | N6: =IF('AYIRA MINI MART FINAL MENU - Pr'!N6="", "", 'AYIRA MINI MART FINAL MENU - Pr'!N6)
A7: =IFERROR(__xludf.DUMMYFUNCTION("IF('AYIRA MINI MART FINAL MENU - Pr'!A7="""", """", IF(LEN(IFERROR(TRIM(REGEXREPLACE(TRIM(REGEXEXTRACT('AYIRA MINI MART FINAL MENU - Pr'!A7, ""^[^\x{0600}-\x{06FF}]+"")), ""[-–]+$"", """")), """"))>0, IFERROR(TRIM(REGEXREPLACE(TRIM(REGEXEXTRACT('AYIRA MIN"&"I MART FINAL MENU - Pr'!A7, ""^[^\x{0600}-\x{06FF}]+"")), ""[-–]+$"", """")), """"), GOOGLETRANSLATE('AYIRA MINI MART FINAL MENU - Pr'!A7, ""ar"", ""en"")))"),"7Up 330ml") -> 7Up 330ml | B7: =IFERROR(__xludf.DUMMYFUNCTION("IF('AYIRA MINI MART FINAL MENU - Pr'!B7="""", """", IF(LEN(IFERROR(TRIM(REGEXREPLACE(TRIM(REGEXEXTRACT('AYIRA MINI MART FINAL MENU - Pr'!B7, ""^[^\x{0600}-\x{06FF}]+"")), ""[-–]+$"", """")), """"))>0, IFERROR(TRIM(REGEXREPLACE(TRIM(REGEXEXTRACT('AYIRA MIN"&"I MART FINAL MENU - Pr'!B7, ""^[^\x{0600}-\x{06FF}]+"")), ""[-–]+$"", """")), """"), GOOGLETRANSLATE('AYIRA MINI MART FINAL MENU - Pr'!B7, ""ar"", ""en"")))"),"Carbonated Soft Drinks") -> Carbonated Soft Drinks | C7: =IF('AYIRA MINI MART FINAL MENU - Pr'!C7="", "", 'AYIRA MINI MART FINAL MENU - Pr'!C7) -> 2.5 | D7: =IFERROR(__xludf.DUMMYFUNCTION("IF('AYIRA MINI MART FINAL MENU - Pr'!D7="""", """", GOOGLETRANSLATE('AYIRA MINI MART FINAL MENU - Pr'!D7, ""ar"", ""en""))"),"Enjoy 7UP, the refreshing soft drink that gives you energy and vitality with every drop. Its great taste and unique formula make it the perfect choice to quench your thirst anytime. Ideal for parties, family gatherings, and various occasions. It boasts di"&"stinctive flavors that make every sip an unforgettable experience. Get it now from Aira Mini Mart at the best prices and highest quality. Our premium drink provides instant refreshment and satisfies your discerning palate whenever you need hydration.") -> Enjoy 7UP, the refreshing soft drink that gives you energy and vitality with every drop. Its great taste and unique formula make it the perfect choice to quench your thirst anytime. Ideal for parties, family gatherings, and various occasions. It boasts distinctive flavors that make every sip an unforgettable experience. Get it now from Aira Mini Mart at the best prices and highest quality. Our premium drink provides instant refreshment and satisfies your discerning palate whenever you need hydration. | E7: =IF('AYIRA MINI MART FINAL MENU - Pr'!K7="", "", 'AYIRA MINI MART FINAL MENU - Pr'!K7) | L7: =IF('AYIRA MINI MART FINAL MENU - Pr'!L7="", "", 'AYIRA MINI MART FINAL MENU - Pr'!L7) | M7: =IF('AYIRA MINI MART FINAL MENU - Pr'!M7="", "", 'AYIRA MINI MART FINAL MENU - Pr'!M7) | N7: =IF('AYIRA MINI MART FINAL MENU - Pr'!N7="", "", 'AYIRA MINI MART FINAL MENU - Pr'!N7)
A8: =IFERROR(__xludf.DUMMYFUNCTION("IF('AYIRA MINI MART FINAL MENU - Pr'!A8="""", """", IF(LEN(IFERROR(TRIM(REGEXREPLACE(TRIM(REGEXEXTRACT('AYIRA MINI MART FINAL MENU - Pr'!A8, ""^[^\x{0600}-\x{06FF}]+"")), ""[-–]+$"", """")), """"))>0, IFERROR(TRIM(REGEXREPLACE(TRIM(REGEXEXTRACT('AYIRA MIN"&"I MART FINAL MENU - Pr'!A8, ""^[^\x{0600}-\x{06FF}]+"")), ""[-–]+$"", """")), """"), GOOGLETRANSLATE('AYIRA MINI MART FINAL MENU - Pr'!A8, ""ar"", ""en"")))"),"Mirinda Orange 1.25L") -> Mirinda Orange 1.25L | B8: =IFERROR(__xludf.DUMMYFUNCTION("IF('AYIRA MINI MART FINAL MENU - Pr'!B8="""", """", IF(LEN(IFERROR(TRIM(REGEXREPLACE(TRIM(REGEXEXTRACT('AYIRA MINI MART FINAL MENU - Pr'!B8, ""^[^\x{0600}-\x{06FF}]+"")), ""[-–]+$"", """")), """"))>0, IFERROR(TRIM(REGEXREPLACE(TRIM(REGEXEXTRACT('AYIRA MIN"&"I MART FINAL MENU - Pr'!B8, ""^[^\x{0600}-\x{06FF}]+"")), ""[-–]+$"", """")), """"), GOOGLETRANSLATE('AYIRA MINI MART FINAL MENU - Pr'!B8, ""ar"", ""en"")))"),"Carbonated Soft Drinks") -> Carbonated Soft Drinks | C8: =IF('AYIRA MINI MART FINAL MENU - Pr'!C8="", "", 'AYIRA MINI MART FINAL MENU - Pr'!C8) -> 4.5 | D8: =IFERROR(__xludf.DUMMYFUNCTION("IF('AYIRA MINI MART FINAL MENU - Pr'!D8="""", """", GOOGLETRANSLATE('AYIRA MINI MART FINAL MENU - Pr'!D8, ""ar"", ""en""))"),"Enjoy Miranda, the refreshing soft drink that gives you energy and vitality with every drop. Its great taste and unique formula make it the perfect choice to quench your thirst anytime. Ideal for parties, family gatherings, and various occasions. It boast"&"s distinctive flavors that make every sip an unforgettable experience. Get it now from Aira Mini Mart at the best prices and highest quality. Our premium drink provides instant refreshment and satisfies your discerning palate whenever you need hydration.") -> Enjoy Miranda, the refreshing soft drink that gives you energy and vitality with every drop. Its great taste and unique formula make it the perfect choice to quench your thirst anytime. Ideal for parties, family gatherings, and various occasions. It boasts distinctive flavors that make every sip an unforgettable experience. Get it now from Aira Mini Mart at the best prices and highest quality. Our premium drink provides instant refreshment and satisfies your discerning palate whenever you need hydration. | E8: =IF('AYIRA MINI MART FINAL MENU - Pr'!K8="", "", 'AYIRA MINI MART FINAL MENU - Pr'!K8) | L8: =IF('AYIRA MINI MART FINAL MENU - Pr'!L8="", "", 'AYIRA MINI MART FINAL MENU - Pr'!L8) | M8: =IF('AYIRA MINI MART FINAL MENU - Pr'!M8="", "", 'AYIRA MINI MART FINAL MENU - Pr'!M8) | N8: =IF('AYIRA MINI MART FINAL MENU - Pr'!N8="", "", 'AYIRA MINI MART FINAL MENU - Pr'!N8)
A9: =IFERROR(__xludf.DUMMYFUNCTION("IF('AYIRA MINI MART FINAL MENU - Pr'!A9="""", """", IF(LEN(IFERROR(TRIM(REGEXREPLACE(TRIM(REGEXEXTRACT('AYIRA MINI MART FINAL MENU - Pr'!A9, ""^[^\x{0600}-\x{06FF}]+"")), ""[-–]+$"", """")), """"))>0, IFERROR(TRIM(REGEXREPLACE(TRIM(REGEXEXTRACT('AYIRA MIN"&"I MART FINAL MENU - Pr'!A9, ""^[^\x{0600}-\x{06FF}]+"")), ""[-–]+$"", """")), """"), GOOGLETRANSLATE('AYIRA MINI MART FINAL MENU - Pr'!A9, ""ar"", ""en"")))"),"Red Bull Sugar Free 250ml") -> Red Bull Sugar Free 250ml | B9: =IFERROR(__xludf.DUMMYFUNCTION("IF('AYIRA MINI MART FINAL MENU - Pr'!B9="""", """", IF(LEN(IFERROR(TRIM(REGEXREPLACE(TRIM(REGEXEXTRACT('AYIRA MINI MART FINAL MENU - Pr'!B9, ""^[^\x{0600}-\x{06FF}]+"")), ""[-–]+$"", """")), """"))>0, IFERROR(TRIM(REGEXREPLACE(TRIM(REGEXEXTRACT('AYIRA MIN"&"I MART FINAL MENU - Pr'!B9, ""^[^\x{0600}-\x{06FF}]+"")), ""[-–]+$"", """")), """"), GOOGLETRANSLATE('AYIRA MINI MART FINAL MENU - Pr'!B9, ""ar"", ""en"")))"),"Energy & Sports Drinks") -> Energy & Sports Drinks | C9: =IF('AYIRA MINI MART FINAL MENU - Pr'!C9="", "", 'AYIRA MINI MART FINAL MENU - Pr'!C9) -> 10 | D9: =IFERROR(__xludf.DUMMYFUNCTION("IF('AYIRA MINI MART FINAL MENU - Pr'!D9="""", """", GOOGLETRANSLATE('AYIRA MINI MART FINAL MENU - Pr'!D9, ""ar"", ""en""))"),"Fuel your energy with Red Bull, the favorite energy drink of athletes and professionals. It gives you the focus and stamina you need to tackle the day's challenges with peak performance. With a unique blend of caffeine, vitamins, and amino acids, it helps"&" you perform at your best. Perfect before a workout or during long work hours. Experience the difference with every sip and enjoy unparalleled energy. Available now at Aira Mini Mart at an affordable price and with guaranteed quality.") -> Fuel your energy with Red Bull, the favorite energy drink of athletes and professionals. It gives you the focus and stamina you need to tackle the day's challenges with peak performance. With a unique blend of caffeine, vitamins, and amino acids, it helps you perform at your best. Perfect before a workout or during long work hours. Experience the difference with every sip and enjoy unparalleled energy. Available now at Aira Mini Mart at an affordable price and with guaranteed quality. | E9: =IF('AYIRA MINI MART FINAL MENU - Pr'!K9="", "", 'AYIRA MINI MART FINAL MENU - Pr'!K9) | L9: =IF('AYIRA MINI MART FINAL MENU - Pr'!L9="", "", 'AYIRA MINI MART FINAL MENU - Pr'!L9) | M9: =IF('AYIRA MINI MART FINAL MENU - Pr'!M9="", "", 'AYIRA MINI MART FINAL MENU - Pr'!M9) | N9: =IF('AYIRA MINI MART FINAL MENU - Pr'!N9="", "", 'AYIRA MINI MART FINAL MENU - Pr'!N9)
A10: =IFERROR(__xludf.DUMMYFUNCTION("IF('AYIRA MINI MART FINAL MENU - Pr'!A10="""", """", IF(LEN(IFERROR(TRIM(REGEXREPLACE(TRIM(REGEXEXTRACT('AYIRA MINI MART FINAL MENU - Pr'!A10, ""^[^\x{0600}-\x{06FF}]+"")), ""[-–]+$"", """")), """"))>0, IFERROR(TRIM(REGEXREPLACE(TRIM(REGEXEXTRACT('AYIRA M"&"INI MART FINAL MENU - Pr'!A10, ""^[^\x{0600}-\x{06FF}]+"")), ""[-–]+$"", """")), """"), GOOGLETRANSLATE('AYIRA MINI MART FINAL MENU - Pr'!A10, ""ar"", ""en"")))"),"Red Bull Sea Blue Edition 250ml") -> Red Bull Sea Blue Edition 250ml | B10: =IFERROR(__xludf.DUMMYFUNCTION("IF('AYIRA MINI MART FINAL MENU - Pr'!B10="""", """", IF(LEN(IFERROR(TRIM(REGEXREPLACE(TRIM(REGEXEXTRACT('AYIRA MINI MART FINAL MENU - Pr'!B10, ""^[^\x{0600}-\x{06FF}]+"")), ""[-–]+$"", """")), """"))>0, IFERROR(TRIM(REGEXREPLACE(TRIM(REGEXEXTRACT('AYIRA M"&"INI MART FINAL MENU - Pr'!B10, ""^[^\x{0600}-\x{06FF}]+"")), ""[-–]+$"", """")), """"), GOOGLETRANSLATE('AYIRA MINI MART FINAL MENU - Pr'!B10, ""ar"", ""en"")))"),"Energy & Sports Drinks") -> Energy & Sports Drinks | C10: =IF('AYIRA MINI MART FINAL MENU - Pr'!C10="", "", 'AYIRA MINI MART FINAL MENU - Pr'!C10) -> 10 | D10: =IFERROR(__xludf.DUMMYFUNCTION("IF('AYIRA MINI MART FINAL MENU - Pr'!D10="""", """", GOOGLETRANSLATE('AYIRA MINI MART FINAL MENU - Pr'!D10, ""ar"", ""en""))"),"Fuel your energy with Red Bull, the favorite energy drink of athletes and professionals. It gives you the focus and stamina you need to tackle the day's challenges with peak performance. With a unique blend of caffeine, vitamins, and amino acids, it helps"&" you perform at your best. Perfect before a workout or during long work hours. Experience the difference with every sip and enjoy unparalleled energy. Available now at Aira Mini Mart at an affordable price and with guaranteed quality.") -> Fuel your energy with Red Bull, the favorite energy drink of athletes and professionals. It gives you the focus and stamina you need to tackle the day's challenges with peak performance. With a unique blend of caffeine, vitamins, and amino acids, it helps you perform at your best. Perfect before a workout or during long work hours. Experience the difference with every sip and enjoy unparalleled energy. Available now at Aira Mini Mart at an affordable price and with guaranteed quality. | E10: =IF('AYIRA MINI MART FINAL MENU - Pr'!K10="", "", 'AYIRA MINI MART FINAL MENU - Pr'!K10) | L10: =IF('AYIRA MINI MART FINAL MENU - Pr'!L10="", "", 'AYIRA MINI MART FINAL MENU - Pr'!L10) | M10: =IF('AYIRA MINI MART FINAL MENU - Pr'!M10="", "", 'AYIRA MINI MART FINAL MENU - Pr'!M10) | N10: =IF('AYIRA MINI MART FINAL MENU - Pr'!N10="", "", 'AYIRA MINI MART FINAL MENU - Pr'!N10)
A11: =IFERROR(__xludf.DUMMYFUNCTION("IF('AYIRA MINI MART FINAL MENU - Pr'!A11="""", """", IF(LEN(IFERROR(TRIM(REGEXREPLACE(TRIM(REGEXEXTRACT('AYIRA MINI MART FINAL MENU - Pr'!A11, ""^[^\x{0600}-\x{06FF}]+"")), ""[-–]+$"", """")), """"))>0, IFERROR(TRIM(REGEXREPLACE(TRIM(REGEXEXTRACT('AYIRA M"&"INI MART FINAL MENU - Pr'!A11, ""^[^\x{0600}-\x{06FF}]+"")), ""[-–]+$"", """")), """"), GOOGLETRANSLATE('AYIRA MINI MART FINAL MENU - Pr'!A11, ""ar"", ""en"")))"),"Red Bull White Edition Coconut Berry 250ml") -> Red Bull White Edition Coconut Berry 250ml | B11: =IFERROR(__xludf.DUMMYFUNCTION("IF('AYIRA MINI MART FINAL MENU - Pr'!B11="""", """", IF(LEN(IFERROR(TRIM(REGEXREPLACE(TRIM(REGEXEXTRACT('AYIRA MINI MART FINAL MENU - Pr'!B11, ""^[^\x{0600}-\x{06FF}]+"")), ""[-–]+$"", """")), """"))>0, IFERROR(TRIM(REGEXREPLACE(TRIM(REGEXEXTRACT('AYIRA M"&"INI MART FINAL MENU - Pr'!B11, ""^[^\x{0600}-\x{06FF}]+"")), ""[-–]+$"", """")), """"), GOOGLETRANSLATE('AYIRA MINI MART FINAL MENU - Pr'!B11, ""ar"", ""en"")))"),"Energy & Sports Drinks") -> Energy & Sports Drinks | C11: =IF('AYIRA MINI MART FINAL MENU - Pr'!C11="", "", 'AYIRA MINI MART FINAL MENU - Pr'!C11) -> 10 | D11: =IFERROR(__xludf.DUMMYFUNCTION("IF('AYIRA MINI MART FINAL MENU - Pr'!D11="""", """", GOOGLETRANSLATE('AYIRA MINI MART FINAL MENU - Pr'!D11, ""ar"", ""en""))"),"Fuel your energy with Red Bull, the favorite energy drink of athletes and professionals. It gives you the focus and stamina you need to tackle the day's challenges with peak performance. With a unique blend of caffeine, vitamins, and amino acids, it helps"&" you perform at your best. Perfect before a workout or during long work hours. Experience the difference with every sip and enjoy unparalleled energy. Available now at Aira Mini Mart at an affordable price and with guaranteed quality.") -> Fuel your energy with Red Bull, the favorite energy drink of athletes and professionals. It gives you the focus and stamina you need to tackle the day's challenges with peak performance. With a unique blend of caffeine, vitamins, and amino acids, it helps you perform at your best. Perfect before a workout or during long work hours. Experience the difference with every sip and enjoy unparalleled energy. Available now at Aira Mini Mart at an affordable price and with guaranteed quality. | E11: =IF('AYIRA MINI MART FINAL MENU - Pr'!K11="", "", 'AYIRA MINI MART FINAL MENU - Pr'!K11) | L11: =IF('AYIRA MINI MART FINAL MENU - Pr'!L11="", "", 'AYIRA MINI MART FINAL MENU - Pr'!L11) | M11: =IF('AYIRA MINI MART FINAL MENU - Pr'!M11="", "", 'AYIRA MINI MART FINAL MENU - Pr'!M11) | N11: =IF('AYIRA MINI MART FINAL MENU - Pr'!N11="", "", 'AYIRA MINI MART FINAL MENU - Pr'!N11)
A12: =IFERROR(__xludf.DUMMYFUNCTION("IF('AYIRA MINI MART FINAL MENU - Pr'!A12="""", """", IF(LEN(IFERROR(TRIM(REGEXREPLACE(TRIM(REGEXEXTRACT('AYIRA MINI MART FINAL MENU - Pr'!A12, ""^[^\x{0600}-\x{06FF}]+"")), ""[-–]+$"", """")), """"))>0, IFERROR(TRIM(REGEXREPLACE(TRIM(REGEXEXTRACT('AYIRA M"&"INI MART FINAL MENU - Pr'!A12, ""^[^\x{0600}-\x{06FF}]+"")), ""[-–]+$"", """")), """"), GOOGLETRANSLATE('AYIRA MINI MART FINAL MENU - Pr'!A12, ""ar"", ""en"")))"),"Red Bull Energy Drink 250ml") -> Red Bull Energy Drink 250ml | B12: =IFERROR(__xludf.DUMMYFUNCTION("IF('AYIRA MINI MART FINAL MENU - Pr'!B12="""", """", IF(LEN(IFERROR(TRIM(REGEXREPLACE(TRIM(REGEXEXTRACT('AYIRA MINI MART FINAL MENU - Pr'!B12, ""^[^\x{0600}-\x{06FF}]+"")), ""[-–]+$"", """")), """"))>0, IFERROR(TRIM(REGEXREPLACE(TRIM(REGEXEXTRACT('AYIRA M"&"INI MART FINAL MENU - Pr'!B12, ""^[^\x{0600}-\x{06FF}]+"")), ""[-–]+$"", """")), """"), GOOGLETRANSLATE('AYIRA MINI MART FINAL MENU - Pr'!B12, ""ar"", ""en"")))"),"Energy & Sports Drinks") -> Energy & Sports Drinks | C12: =IF('AYIRA MINI MART FINAL MENU - Pr'!C12="", "", 'AYIRA MINI MART FINAL MENU - Pr'!C12) -> 10 | D12: =IFERROR(__xludf.DUMMYFUNCTION("IF('AYIRA MINI MART FINAL MENU - Pr'!D12="""", """", GOOGLETRANSLATE('AYIRA MINI MART FINAL MENU - Pr'!D12, ""ar"", ""en""))"),"Fuel your energy with Red Bull, the favorite energy drink of athletes and professionals. It gives you the focus and stamina you need to tackle the day's challenges with peak performance. With a unique blend of caffeine, vitamins, and amino acids, it helps"&" you perform at your best. Perfect before a workout or during long work hours. Experience the difference with every sip and enjoy unparalleled energy. Available now at Aira Mini Mart at an affordable price and with guaranteed quality.") -> Fuel your energy with Red Bull, the favorite energy drink of athletes and professionals. It gives you the focus and stamina you need to tackle the day's challenges with peak performance. With a unique blend of caffeine, vitamins, and amino acids, it helps you perform at your best. Perfect before a workout or during long work hours. Experience the difference with every sip and enjoy unparalleled energy. Available now at Aira Mini Mart at an affordable price and with guaranteed quality. | E12: =IF('AYIRA MINI MART FINAL MENU - Pr'!K12="", "", 'AYIRA MINI MART FINAL MENU - Pr'!K12) | L12: =IF('AYIRA MINI MART FINAL MENU - Pr'!L12="", "", 'AYIRA MINI MART FINAL MENU - Pr'!L12) | M12: =IF('AYIRA MINI MART FINAL MENU - Pr'!M12="", "", 'AYIRA MINI MART FINAL MENU - Pr'!M12) | N12: =IF('AYIRA MINI MART FINAL MENU - Pr'!N12="", "", 'AYIRA MINI MART FINAL MENU - Pr'!N12)
A13: =IFERROR(__xludf.DUMMYFUNCTION("IF('AYIRA MINI MART FINAL MENU - Pr'!A13="""", """", IF(LEN(IFERROR(TRIM(REGEXREPLACE(TRIM(REGEXEXTRACT('AYIRA MINI MART FINAL MENU - Pr'!A13, ""^[^\x{0600}-\x{06FF}]+"")), ""[-–]+$"", """")), """"))>0, IFERROR(TRIM(REGEXREPLACE(TRIM(REGEXEXTRACT('AYIRA M"&"INI MART FINAL MENU - Pr'!A13, ""^[^\x{0600}-\x{06FF}]+"")), ""[-–]+$"", """")), """"), GOOGLETRANSLATE('AYIRA MINI MART FINAL MENU - Pr'!A13, ""ar"", ""en"")))"),"Coca-Cola Sleek Can 330ml") -> Coca-Cola Sleek Can 330ml | B13: =IFERROR(__xludf.DUMMYFUNCTION("IF('AYIRA MINI MART FINAL MENU - Pr'!B13="""", """", IF(LEN(IFERROR(TRIM(REGEXREPLACE(TRIM(REGEXEXTRACT('AYIRA MINI MART FINAL MENU - Pr'!B13, ""^[^\x{0600}-\x{06FF}]+"")), ""[-–]+$"", """")), """"))>0, IFERROR(TRIM(REGEXREPLACE(TRIM(REGEXEXTRACT('AYIRA M"&"INI MART FINAL MENU - Pr'!B13, ""^[^\x{0600}-\x{06FF}]+"")), ""[-–]+$"", """")), """"), GOOGLETRANSLATE('AYIRA MINI MART FINAL MENU - Pr'!B13, ""ar"", ""en"")))"),"Carbonated Soft Drinks") -> Carbonated Soft Drinks | C13: =IF('AYIRA MINI MART FINAL MENU - Pr'!C13="", "", 'AYIRA MINI MART FINAL MENU - Pr'!C13) -> 2.5 | D13: =IFERROR(__xludf.DUMMYFUNCTION("IF('AYIRA MINI MART FINAL MENU - Pr'!D13="""", """", GOOGLETRANSLATE('AYIRA MINI MART FINAL MENU - Pr'!D13, ""ar"", ""en""))"),"Enjoy Coca-Cola, the refreshing soft drink that gives you energy and vitality with every sip. Its great taste and unique formula make it the perfect choice to quench your thirst anytime. Ideal for parties, family gatherings, and various occasions. It cont"&"ains distinctive flavors that make every sip an unforgettable experience. Get it now from Aira Mini Mart at the best prices and highest quality. Our premium drink provides instant refreshment and satisfies your discerning palate whenever you need hydratio"&"n.") -> Enjoy Coca-Cola, the refreshing soft drink that gives you energy and vitality with every sip. Its great taste and unique formula make it the perfect choice to quench your thirst anytime. Ideal for parties, family gatherings, and various occasions. It contains distinctive flavors that make every sip an unforgettable experience. Get it now from Aira Mini Mart at the best prices and highest quality. Our premium drink provides instant refreshment and satisfies your discerning palate whenever you need hydration. | E13: =IF('AYIRA MINI MART FINAL MENU - Pr'!K13="", "", 'AYIRA MINI MART FINAL MENU - Pr'!K13) | L13: =IF('AYIRA MINI MART FINAL MENU - Pr'!L13="", "", 'AYIRA MINI MART FINAL MENU - Pr'!L13) | M13: =IF('AYIRA MINI MART FINAL MENU - Pr'!M13="", "", 'AYIRA MINI MART FINAL MENU - Pr'!M13) | N13: =IF('AYIRA MINI MART FINAL MENU - Pr'!N13="", "", 'AYIRA MINI MART FINAL MENU - Pr'!N13)
